Workbook

Sheet Где поесть
A1: Категория | B1: Подкатегория | C1: Название | D1: Описание | F1: Адрес | G1: Район | H1: Координаты | I1: Ссылка на фото | J1: Bконтакте | K1: Telegram | L1: Instagram | M1: Сайт | N1: Телефон | O1: Bремя работы | P1: Меню Справочник
A2: Кофе | C2: Кофе в Окнах | D2: ✔️Кофе с качеством, которое чувствуется в каждой чашке ✔️ Уникальные лоты со всего мира ✔️ Зерно и дрипы для дома | F2: ул. Розы Люксембург 40/10 | G2: Корабелка | H2: 44.610761, 33.542573 | I2: https://avatars.mds.yandex.net/get-altay/9749133/2a00000188ed549fcfea4a2736bb828f6097/XXXL | J2: https://vk.com/kofevoknah | K2: https://t.me/coffee_v_oknah | N2: +7 (979) 054-14-95 | O2: ⌚️Пн-Пт: с 7:30 до 20:00 Сб-Вс: с 8:30 до 20:00 | P2: {=_xlfn.XLOOKUP(C2, 'Меню Справочник'!A:A, 'Меню Справочник'!D:D, "Меню не заполнено")} -> ЧЕРНЫЙ КОФЕ Эспрессо — 130р 20мл / 170р 40мл Американо — 130р 180мл / 170р 250мл Фильтр — 180р 250 мл / 240р 350мл Воронка — 290р 250мл С МОЛОКОМ Капучино — 190р 250мл / 260р 350мл Латте — 220р 350мл / 290р 480мл Флэт Уайт — 240р 250мл / 290р 350мл Раф (ваниль, лаванда, сол. карамель) — 260р 250мл / 360р 350мл Сол. Карамель — 230р 250мл / 280р 350мл Ореховый кофе — 260р 250 мл / 350р 350мл ДОБАВКИ На растительном — 50р 250мл / 70р 350мл / 90р 480мл Доп. эспрессо — 60р 20мл Кедр — 100р 20г Зефир — 40р 15г Молоко — 20р 50мл Сливки — 40р 50мл Сироп — 50р 20мл ХОЛОДНЫЙ КОФЕ Айс-латте — 220р 375 мл / 280р 500мл Айс-латте (ваниль, лаванда, сол. карамель) — 260р 375 мл / 320р 500мл Фраппе (ваниль, лаванда, сол. карамель) — 240р 375 мл / 290р 500мл Бамбл (апельсин, вишня) — 290р 375мл / 370р 500мл По-севастопольски — 290р 375мл / 390р 500мл Эспрессо-тоник — 260р 375мл / 320р 500мл ХОЛОДНЫЕ НАПИТКИ Крафтовый тоник — 220р 375мл / 280р 500мл Лавандовый лимонад — 200р 375 мл / 240р 500мл Цитрусовый лимонад — 200р 375 мл / 250р 500мл Ягодный лимонад — 240р 375мл / 280р 500мл Молочный коктейль — 250р 375мл / 290р 500мл ЧАЙ Заварной чай — 100р 350мл / 130р 480мл Китайский — 160р 350 мл / 200р 480мл Облепиховый — 240р 350мл / 320р 480мл Ягоды-апельсин — 220р 350мл / 280р 480мл Лимон-имбирь — 220р 350мл / 280р 480мл Матча-латте — 170р 250мл / 240р 350мл ГОРЯЧИЕ НАПИТКИ Какао — 160р 250 мл / 220р 350мл Ореховое какао — 240р 250мл / 320р 350мл Горячий шоколад — 180р 180мл / 240р 250мл
A3: Кофе | C3: Кофе в Окнах | D3: ✔️Кофе с качеством, которое чувствуется в каждой чашке ✔️ Уникальные лоты со всего мира ✔️ Зерно и дрипы для дома | F3: ул. Большая Морская 8 | G3: Центр | H3: 44.609488, 33.520722 | I3: https://avatars.mds.yandex.net/get-altay/903198/2a00000188e7458f8be9551542494903d8e4/XXXL | J3: https://vk.com/kofevoknah | K3: https://t.me/coffee_v_oknah | N3: +7 (979) 054-14-95 | O3: ⌚️Пн-Пт: с 7:30 до 21:00 Сб-Вс: с 8:30 до 21:00 | P3: {=_xlfn.XLOOKUP(C3, 'Меню Справочник'!A:A, 'Меню Справочник'!D:D, "Меню не заполнено")} -> ЧЕРНЫЙ КОФЕ Эспрессо — 130р 20мл / 170р 40мл Американо — 130р 180мл / 170р 250мл Фильтр — 180р 250 мл / 240р 350мл Воронка — 290р 250мл С МОЛОКОМ Капучино — 190р 250мл / 260р 350мл Латте — 220р 350мл / 290р 480мл Флэт Уайт — 240р 250мл / 290р 350мл Раф (ваниль, лаванда, сол. карамель) — 260р 250мл / 360р 350мл Сол. Карамель — 230р 250мл / 280р 350мл Ореховый кофе — 260р 250 мл / 350р 350мл ДОБАВКИ На растительном — 50р 250мл / 70р 350мл / 90р 480мл Доп. эспрессо — 60р 20мл Кедр — 100р 20г Зефир — 40р 15г Молоко — 20р 50мл Сливки — 40р 50мл Сироп — 50р 20мл ХОЛОДНЫЙ КОФЕ Айс-латте — 220р 375 мл / 280р 500мл Айс-латте (ваниль, лаванда, сол. карамель) — 260р 375 мл / 320р 500мл Фраппе (ваниль, лаванда, сол. карамель) — 240р 375 мл / 290р 500мл Бамбл (апельсин, вишня) — 290р 375мл / 370р 500мл По-севастопольски — 290р 375мл / 390р 500мл Эспрессо-тоник — 260р 375мл / 320р 500мл ХОЛОДНЫЕ НАПИТКИ Крафтовый тоник — 220р 375мл / 280р 500мл Лавандовый лимонад — 200р 375 мл / 240р 500мл Цитрусовый лимонад — 200р 375 мл / 250р 500мл Ягодный лимонад — 240р 375мл / 280р 500мл Молочный коктейль — 250р 375мл / 290р 500мл ЧАЙ Заварной чай — 100р 350мл / 130р 480мл Китайский — 160р 350 мл / 200р 480мл Облепиховый — 240р 350мл / 320р 480мл Ягоды-апельсин — 220р 350мл / 280р 480мл Лимон-имбирь — 220р 350мл / 280р 480мл Матча-латте — 170р 250мл / 240р 350мл ГОРЯЧИЕ НАПИТКИ Какао — 160р 250 мл / 220р 350мл Ореховое какао — 240р 250мл / 320р 350мл Горячий шоколад — 180р 180мл / 240р 250мл
A4: Кофе | C4: Кофе в Окнах | D4: ✔️Кофе с качеством, которое чувствуется в каждой чашке ✔️ Уникальные лоты со всего мира ✔️ Зерно и дрипы для дома | F4: ул. Советская 12 | G4: Центр | H4: 44.610127, 33.524399 | I4: https://avatars.mds.yandex.net/get-altay/1028115/2a00000188ddd16fa3b4d71efc0aa1c93669/XXXL | J4: https://vk.com/kofevoknah | K4: https://t.me/coffee_v_oknah | N4: +7 (979) 054-14-95 | O4: ⌚️Пн-Пт: с 7:30 до 20:00 Сб-Вс: с 8:30 до 20:00 | P4: {=_xlfn.XLOOKUP(C4, 'Меню Справочник'!A:A, 'Меню Справочник'!D:D, "Меню не заполнено")} -> ЧЕРНЫЙ КОФЕ Эспрессо — 130р 20мл / 170р 40мл Американо — 130р 180мл / 170р 250мл Фильтр — 180р 250 мл / 240р 350мл Воронка — 290р 250мл С МОЛОКОМ Капучино — 190р 250мл / 260р 350мл Латте — 220р 350мл / 290р 480мл Флэт Уайт — 240р 250мл / 290р 350мл Раф (ваниль, лаванда, сол. карамель) — 260р 250мл / 360р 350мл Сол. Карамель — 230р 250мл / 280р 350мл Ореховый кофе — 260р 250 мл / 350р 350мл ДОБАВКИ На растительном — 50р 250мл / 70р 350мл / 90р 480мл Доп. эспрессо — 60р 20мл Кедр — 100р 20г Зефир — 40р 15г Молоко — 20р 50мл Сливки — 40р 50мл Сироп — 50р 20мл ХОЛОДНЫЙ КОФЕ Айс-латте — 220р 375 мл / 280р 500мл Айс-латте (ваниль, лаванда, сол. карамель) — 260р 375 мл / 320р 500мл Фраппе (ваниль, лаванда, сол. карамель) — 240р 375 мл / 290р 500мл Бамбл (апельсин, вишня) — 290р 375мл / 370р 500мл По-севастопольски — 290р 375мл / 390р 500мл Эспрессо-тоник — 260р 375мл / 320р 500мл ХОЛОДНЫЕ НАПИТКИ Крафтовый тоник — 220р 375мл / 280р 500мл Лавандовый лимонад — 200р 375 мл / 240р 500мл Цитрусовый лимонад — 200р 375 мл / 250р 500мл Ягодный лимонад — 240р 375мл / 280р 500мл Молочный коктейль — 250р 375мл / 290р 500мл ЧАЙ Заварной чай — 100р 350мл / 130р 480мл Китайский — 160р 350 мл / 200р 480мл Облепиховый — 240р 350мл / 320р 480мл Ягоды-апельсин — 220р 350мл / 280р 480мл Лимон-имбирь — 220р 350мл / 280р 480мл Матча-латте — 170р 250мл / 240р 350мл ГОРЯЧИЕ НАПИТКИ Какао — 160р 250 мл / 220р 350мл Ореховое какао — 240р 250мл / 320р 350мл Горячий шоколад — 180р 180мл / 240р 250мл
A5: Кофе | C5: Кофе в Окнах | D5: ✔️Кофе с качеством, которое чувствуется в каждой чашке ✔️ Уникальные лоты со всего мира ✔️ Зерно и дрипы для дома | F5: ул. Пушкина 4 | G5: Центр | H5: 44.604957, 33.528082 | I5: https://avatars.mds.yandex.net/get-altay/15438512/2a00000198410544881d9175fa9ced8ef267/XXXL | J5: https://vk.com/kofevoknah | K5: https://t.me/coffee_v_oknah | N5: +7 (979) 054-14-95 | O5: ⌚️Пн-Пт: с 7:30 до 20:00 Сб-Вс: с 8:30 до 20:00 | P5: {=_xlfn.XLOOKUP(C5, 'Меню Справочник'!A:A, 'Меню Справочник'!D:D, "Меню не заполнено")} -> ЧЕРНЫЙ КОФЕ Эспрессо — 130р 20мл / 170р 40мл Американо — 130р 180мл / 170р 250мл Фильтр — 180р 250 мл / 240р 350мл Воронка — 290р 250мл С МОЛОКОМ Капучино — 190р 250мл / 260р 350мл Латте — 220р 350мл / 290р 480мл Флэт Уайт — 240р 250мл / 290р 350мл Раф (ваниль, лаванда, сол. карамель) — 260р 250мл / 360р 350мл Сол. Карамель — 230р 250мл / 280р 350мл Ореховый кофе — 260р 250 мл / 350р 350мл ДОБАВКИ На растительном — 50р 250мл / 70р 350мл / 90р 480мл Доп. эспрессо — 60р 20мл Кедр — 100р 20г Зефир — 40р 15г Молоко — 20р 50мл Сливки — 40р 50мл Сироп — 50р 20мл ХОЛОДНЫЙ КОФЕ Айс-латте — 220р 375 мл / 280р 500мл Айс-латте (ваниль, лаванда, сол. карамель) — 260р 375 мл / 320р 500мл Фраппе (ваниль, лаванда, сол. карамель) — 240р 375 мл / 290р 500мл Бамбл (апельсин, вишня) — 290р 375мл / 370р 500мл По-севастопольски — 290р 375мл / 390р 500мл Эспрессо-тоник — 260р 375мл / 320р 500мл ХОЛОДНЫЕ НАПИТКИ Крафтовый тоник — 220р 375мл / 280р 500мл Лавандовый лимонад — 200р 375 мл / 240р 500мл Цитрусовый лимонад — 200р 375 мл / 250р 500мл Ягодный лимонад — 240р 375мл / 280р 500мл Молочный коктейль — 250р 375мл / 290р 500мл ЧАЙ Заварной чай — 100р 350мл / 130р 480мл Китайский — 160р 350 мл / 200р 480мл Облепиховый — 240р 350мл / 320р 480мл Ягоды-апельсин — 220р 350мл / 280р 480мл Лимон-имбирь — 220р 350мл / 280р 480мл Матча-латте — 170р 250мл / 240р 350мл ГОРЯЧИЕ НАПИТКИ Какао — 160р 250 мл / 220р 350мл Ореховое какао — 240р 250мл / 320р 350мл Горячий шоколад — 180р 180мл / 240р 250мл
A6: Кофе | C6: Кофе в Окнах | D6: ✔️Кофе с качеством, которое чувствуется в каждой чашке ✔️ Уникальные лоты со всего мира ✔️ Зерно и дрипы для дома | F6: Проспект Победы 44/1 | G6: Победа | H6: 44.587467, 33.559295 | I6: https://avatars.mds.yandex.net/get-altay/19593321/2a0000019baa1fbc2f166c8631c4431410f5/XXXL | J6: https://vk.com/kofevoknah | K6: https://t.me/coffee_v_oknah | N6: +7 (979) 054-14-95 | O6: ⌚️Пн-Пт: с 7:30 до 20:00 Сб-Вс: с 8:30 до 20:00 | P6: {=_xlfn.XLOOKUP(C6, 'Меню Справочник'!A:A, 'Меню Справочник'!D:D, "Меню не заполнено")} -> ЧЕРНЫЙ КОФЕ Эспрессо — 130р 20мл / 170р 40мл Американо — 130р 180мл / 170р 250мл Фильтр — 180р 250 мл / 240р 350мл Воронка — 290р 250мл С МОЛОКОМ Капучино — 190р 250мл / 260р 350мл Латте — 220р 350мл / 290р 480мл Флэт Уайт — 240р 250мл / 290р 350мл Раф (ваниль, лаванда, сол. карамель) — 260р 250мл / 360р 350мл Сол. Карамель — 230р 250мл / 280р 350мл Ореховый кофе — 260р 250 мл / 350р 350мл ДОБАВКИ На растительном — 50р 250мл / 70р 350мл / 90р 480мл Доп. эспрессо — 60р 20мл Кедр — 100р 20г Зефир — 40р 15г Молоко — 20р 50мл Сливки — 40р 50мл Сироп — 50р 20мл ХОЛОДНЫЙ КОФЕ Айс-латте — 220р 375 мл / 280р 500мл Айс-латте (ваниль, лаванда, сол. карамель) — 260р 375 мл / 320р 500мл Фраппе (ваниль, лаванда, сол. карамель) — 240р 375 мл / 290р 500мл Бамбл (апельсин, вишня) — 290р 375мл / 370р 500мл По-севастопольски — 290р 375мл / 390р 500мл Эспрессо-тоник — 260р 375мл / 320р 500мл ХОЛОДНЫЕ НАПИТКИ Крафтовый тоник — 220р 375мл / 280р 500мл Лавандовый лимонад — 200р 375 мл / 240р 500мл Цитрусовый лимонад — 200р 375 мл / 250р 500мл Ягодный лимонад — 240р 375мл / 280р 500мл Молочный коктейль — 250р 375мл / 290р 500мл ЧАЙ Заварной чай — 100р 350мл / 130р 480мл Китайский — 160р 350 мл / 200р 480мл Облепиховый — 240р 350мл / 320р 480мл Ягоды-апельсин — 220р 350мл / 280р 480мл Лимон-имбирь — 220р 350мл / 280р 480мл Матча-латте — 170р 250мл / 240р 350мл ГОРЯЧИЕ НАПИТКИ Какао — 160р 250 мл / 220р 350мл Ореховое какао — 240р 250мл / 320р 350мл Горячий шоколад — 180р 180мл / 240р 250мл
A7: Кофе | C7: Кофе в Окнах | D7: ✔️Кофе с качеством, которое чувствуется в каждой чашке ✔️ Уникальные лоты со всего мира ✔️ Зерно и дрипы для дома | F7: ул. Очаковцев 19 | G7: Центр | H7: 44.606020, 33.519841 | I7: https://avatars.mds.yandex.net/get-altay/19871159/2a0000019e4c4c86f2d82975b8ba6c717b15/XXXL | J7: https://vk.com/kofevoknah | K7: https://t.me/coffee_v_oknah | N7: +7 (979) 054-14-95 | O7: ⌚️Пн-Пт: с 7:30 до 20:00 Сб-Вс: с 8:30 до 20:00 | P7: {=_xlfn.XLOOKUP(C7, 'Меню Справочник'!A:A, 'Меню Справочник'!D:D, "Меню не заполнено")} -> ЧЕРНЫЙ КОФЕ Эспрессо — 130р 20мл / 170р 40мл Американо — 130р 180мл / 170р 250мл Фильтр — 180р 250 мл / 240р 350мл Воронка — 290р 250мл С МОЛОКОМ Капучино — 190р 250мл / 260р 350мл Латте — 220р 350мл / 290р 480мл Флэт Уайт — 240р 250мл / 290р 350мл Раф (ваниль, лаванда, сол. карамель) — 260р 250мл / 360р 350мл Сол. Карамель — 230р 250мл / 280р 350мл Ореховый кофе — 260р 250 мл / 350р 350мл ДОБАВКИ На растительном — 50р 250мл / 70р 350мл / 90р 480мл Доп. эспрессо — 60р 20мл Кедр — 100р 20г Зефир — 40р 15г Молоко — 20р 50мл Сливки — 40р 50мл Сироп — 50р 20мл ХОЛОДНЫЙ КОФЕ Айс-латте — 220р 375 мл / 280р 500мл Айс-латте (ваниль, лаванда, сол. карамель) — 260р 375 мл / 320р 500мл Фраппе (ваниль, лаванда, сол. карамель) — 240р 375 мл / 290р 500мл Бамбл (апельсин, вишня) — 290р 375мл / 370р 500мл По-севастопольски — 290р 375мл / 390р 500мл Эспрессо-тоник — 260р 375мл / 320р 500мл ХОЛОДНЫЕ НАПИТКИ Крафтовый тоник — 220р 375мл / 280р 500мл Лавандовый лимонад — 200р 375 мл / 240р 500мл Цитрусовый лимонад — 200р 375 мл / 250р 500мл Ягодный лимонад — 240р 375мл / 280р 500мл Молочный коктейль — 250р 375мл / 290р 500мл ЧАЙ Заварной чай — 100р 350мл / 130р 480мл Китайский — 160р 350 мл / 200р 480мл Облепиховый — 240р 350мл / 320р 480мл Ягоды-апельсин — 220р 350мл / 280р 480мл Лимон-имбирь — 220р 350мл / 280р 480мл Матча-латте — 170р 250мл / 240р 350мл ГОРЯЧИЕ НАПИТКИ Какао — 160р 250 мл / 220р 350мл Ореховое какао — 240р 250мл / 320р 350мл Горячий шоколад — 180р 180мл / 240р 250мл
A8: Кофе | C8: Кофе в Окнах | D8: ✔️Кофе с качеством, которое чувствуется в каждой чашке ✔️ Уникальные лоты со всего мира ✔️ Зерно и дрипы для дома | F8: ул. Bакуленчука 28, стр.1 | G8: Студ.Городок | H8: 44.588917, 33.478666 | I8: https://avatars.mds.yandex.net/get-altay/18730616/2a0000019e5c0ca2f864f7e9a1504c91f091/XXXL | J8: https://vk.com/kofevoknah | K8: https://t.me/coffee_v_oknah | N8: +7 (979) 054-14-95 | O8: ⌚️Пн-Пт: с 7:30 до 20:00 Сб-Вс: с 8:30 до 20:00 | P8: {=_xlfn.XLOOKUP(C8, 'Меню Справочник'!A:A, 'Меню Справочник'!D:D, "Меню не заполнено")} -> ЧЕРНЫЙ КОФЕ Эспрессо — 130р 20мл / 170р 40мл Американо — 130р 180мл / 170р 250мл Фильтр — 180р 250 мл / 240р 350мл Воронка — 290р 250мл С МОЛОКОМ Капучино — 190р 250мл / 260р 350мл Латте — 220р 350мл / 290р 480мл Флэт Уайт — 240р 250мл / 290р 350мл Раф (ваниль, лаванда, сол. карамель) — 260р 250мл / 360р 350мл Сол. Карамель — 230р 250мл / 280р 350мл Ореховый кофе — 260р 250 мл / 350р 350мл ДОБАВКИ На растительном — 50р 250мл / 70р 350мл / 90р 480мл Доп. эспрессо — 60р 20мл Кедр — 100р 20г Зефир — 40р 15г Молоко — 20р 50мл Сливки — 40р 50мл Сироп — 50р 20мл ХОЛОДНЫЙ КОФЕ Айс-латте — 220р 375 мл / 280р 500мл Айс-латте (ваниль, лаванда, сол. карамель) — 260р 375 мл / 320р 500мл Фраппе (ваниль, лаванда, сол. карамель) — 240р 375 мл / 290р 500мл Бамбл (апельсин, вишня) — 290р 375мл / 370р 500мл По-севастопольски — 290р 375мл / 390р 500мл Эспрессо-тоник — 260р 375мл / 320р 500мл ХОЛОДНЫЕ НАПИТКИ Крафтовый тоник — 220р 375мл / 280р 500мл Лавандовый лимонад — 200р 375 мл / 240р 500мл Цитрусовый лимонад — 200р 375 мл / 250р 500мл Ягодный лимонад — 240р 375мл / 280р 500мл Молочный коктейль — 250р 375мл / 290р 500мл ЧАЙ Заварной чай — 100р 350мл / 130р 480мл Китайский — 160р 350 мл / 200р 480мл Облепиховый — 240р 350мл / 320р 480мл Ягоды-апельсин — 220р 350мл / 280р 480мл Лимон-имбирь — 220р 350мл / 280р 480мл Матча-латте — 170р 250мл / 240р 350мл ГОРЯЧИЕ НАПИТКИ Какао — 160р 250 мл / 220р 350мл Ореховое какао — 240р 250мл / 320р 350мл Горячий шоколад — 180р 180мл / 240р 250мл
A9: Кофе | C9: Кофе в Окнах | D9: ✔️Кофе с качеством, которое чувствуется в каждой чашке ✔️ Уникальные лоты со всего мира ✔️ Зерно и дрипы для дома | F9: ул. Адмирала Фадеева 48 | G9: Парк Победы | H9: 44.597698, 33.458579 | I9: https://avatars.mds.yandex.net/get-altay/12728107/2a00000191502cc9d78d35ac9ecfd3eb129c/XXXL | J9: https://vk.com/kofevoknah | K9: https://t.me/coffee_v_oknah | N9: +7 (979) 054-14-95 | O9: ⌚️Пн-Вс 7:30 - 21:00 | P9: {=_xlfn.XLOOKUP(C9, 'Меню Справочник'!A:A, 'Меню Справочник'!D:D, "Меню не заполнено")} -> ЧЕРНЫЙ КОФЕ Эспрессо — 130р 20мл / 170р 40мл Американо — 130р 180мл / 170р 250мл Фильтр — 180р 250 мл / 240р 350мл Воронка — 290р 250мл С МОЛОКОМ Капучино — 190р 250мл / 260р 350мл Латте — 220р 350мл / 290р 480мл Флэт Уайт — 240р 250мл / 290р 350мл Раф (ваниль, лаванда, сол. карамель) — 260р 250мл / 360р 350мл Сол. Карамель — 230р 250мл / 280р 350мл Ореховый кофе — 260р 250 мл / 350р 350мл ДОБАВКИ На растительном — 50р 250мл / 70р 350мл / 90р 480мл Доп. эспрессо — 60р 20мл Кедр — 100р 20г Зефир — 40р 15г Молоко — 20р 50мл Сливки — 40р 50мл Сироп — 50р 20мл ХОЛОДНЫЙ КОФЕ Айс-латте — 220р 375 мл / 280р 500мл Айс-латте (ваниль, лаванда, сол. карамель) — 260р 375 мл / 320р 500мл Фраппе (ваниль, лаванда, сол. карамель) — 240р 375 мл / 290р 500мл Бамбл (апельсин, вишня) — 290р 375мл / 370р 500мл По-севастопольски — 290р 375мл / 390р 500мл Эспрессо-тоник — 260р 375мл / 320р 500мл ХОЛОДНЫЕ НАПИТКИ Крафтовый тоник — 220р 375мл / 280р 500мл Лавандовый лимонад — 200р 375 мл / 240р 500мл Цитрусовый лимонад — 200р 375 мл / 250р 500мл Ягодный лимонад — 240р 375мл / 280р 500мл Молочный коктейль — 250р 375мл / 290р 500мл ЧАЙ Заварной чай — 100р 350мл / 130р 480мл Китайский — 160р 350 мл / 200р 480мл Облепиховый — 240р 350мл / 320р 480мл Ягоды-апельсин — 220р 350мл / 280р 480мл Лимон-имбирь — 220р 350мл / 280р 480мл Матча-латте — 170р 250мл / 240р 350мл ГОРЯЧИЕ НАПИТКИ Какао — 160р 250 мл / 220р 350мл Ореховое какао — 240р 250мл / 320р 350мл Горячий шоколад — 180р 180мл / 240р 250мл
A10: Рестораны | C10: Море | D10: Ресторан «Море» расположено на набережной Парка Победы и предлагает своим гостям разнообразное меню, включающее в себя стейки-гриль, салат «Цезарь», пасту с морепродуктами, блинчики, борщ и многое другое. Интерьер кафе выполнен в морском стиле, а из окон открывается прекрасный вид на море. | F10: наб. Парк Победы 3 | G10: Парк Победы | H10: 44.608534, 33.454720 | I10: https://avatars.mds.yandex.net/get-altay/16329823/2a000001993a0462d136f929582dbdd16904/XXXL | J10: https://vk.com/kafe_mope | N10: +7 (978) 000-25-67 | O10: ⏰ Мы работаем для Вас ежедневно с 09.00 до 23.00 | P10: {=_xlfn.XLOOKUP(C10, 'Меню Справочник'!A:A, 'Меню Справочник'!D:D, "Меню не заполнено")} -> МАНГАЛ • МАНГАЛ-АССОРТИ на 6 человек 3575р 1330гр • МАНГАЛ-АССОРТИ на 4 человека 2550р 970гр • Шашлык из свинины 610р 180гр • Шашлык из куриного филе 570р 180гр • Стейк свиной гриль 750р 400гр • Колбаски гриль 710р 360гр • Лангустины на мангале 970р 320гр • Куриные крылья 720р 360гр • Люля-кебаб из курицы 570р 180гр • Люля-кебаб из баранины 610р 180гр • Рёбра свиные 890р 250гр • Овощи гриль 475р 200гр • Шампиньоны гриль 395р 160гр • Картофель с салом 340р 200гр МОРЕПРОДУКТЫ/РЫБА • Дорадо 450р 100гр • Сибас 450р 100гр • Стейк из сёмги 995р 100гр • Мидии обжаренные с луком 520р 200гр • Креветка в соевом соусе 760р 200гр • Отбивная из рапана 685р 250гр • Мидии в створках в томатном соусе 990р 340гр • Мидии в створках в сырно-сливочном соусе 990р 340гр ЗАКУСКИ ХОЛОДНЫЕ • Фруктовая тарелка 475р 400гр • Овощная нарезка 470р 400гр • Домашние соленья 520р 400гр • Сырное плато 1075р 270гр • Маринованные огурцы 175р 100гр • Паштет из куриной печени с багетом и клюквенным соусом 430р 300гр • Сёмга собственного посола 720р 100гр САЛАТЫ • Салат тёплый с телятиной 720р 300гр • Салат с кальмаром и апельсином 675р 300гр • Салат с сёмгой и авокадо 780р 250гр • Салат "Море" 760р 330гр • Салат "Греческий" 460р 250гр • Салат "Столичный" 460р 230гр • Салат "Домашний" 430р 250гр • Салат с хрустящими баклажанами 580р 235гр • Салат "Цезарь" с куриным филе 520р 250гр • Салат "Цезарь" с креветкой 690р 250гр • Салат "Цезарь" с сёмгой 740р 250гр • "Цезарь" в лаваше с куриным филе 540р 280гр • "Цезарь" в лаваше с сёмгой 760р 280гр СУПЫ • Окрошка на квасе/на кефире 490р 450гр • Борщ красный с говядиной 480р 450гр • Том ям с морепродуктами 770р 350гр • Том ям с курицей 640р 350гр • Грибной крем-суп 390р 300гр • Бульон куриный 290р 450гр • Уха от шефа 490р 450гр ЗАВТРАКИ • Вафли из кабачка 720р 160гр • Английский завтрак 460р 220гр • Омлет 310р 150гр • Омлет с овощами 385р 220гр • Яичница 310р 150гр • Яичница с беконом 395р 220гр • Яичница с овощами 385р 220гр • Манная каша 255р 250гр • Овсяная каша с фруктами 275р 250гр • Сырники со сметаной 420р 150гр ЗАКУСКИ ГОРЯЧИЕ • Сыр халлуми жареный 585р 150гр • Шаурма свиная или куриная 430р 370гр • Шаурма сырная 430р 320гр • Куриные наггетсы 240р 150гр • Сырные палочки в панировке 320р 150гр • Картофель фри 220р 150гр • Картофель по-деревенски 240р 220гр • Драники со сметаной 520р 250гр • Кабачковые оладьи с королевской креветкой 650р 250гр • Бургер 580р 350гр • Black бургер 620р 350гр ДЕТСКОЕ МЕНЮ • Паста детская 390р 200гр • Пюре с куриной котлеткой 370р 250гр • Суп куриный с фрикадельками и макарошками 250р 300гр • Пельмени со сметаной 430р 200гр • Вареники с картошкой со сметаной 370р 250гр ЧЕБУРЕКИ (вес не указан) • С яблоком 135р • С вишней 165р • С брынзой и зеленью 150р • Двойной с брынзой и зеленью 210р • С сыром 150р • Двойной сыр 210р • С сыром и грибами 185р • Свино-говяжий 150р • Двойной свино-говяжий 210р • Свино-говяжий с сыром 210р • Свино-говяжий с грибами 185р • С бараниной 160р • Двойной с бараниной 230р • С бараниной и сыром 220р • С бараниной и грибами 195р ЯНТЫКИ (вес не указан) • С сыром 175р • Двойной сыр 235р • С сыром и грибами 210р • С брынзой и зеленью 175р • Двойной с брынзой и зеленью 235р • Свино-говяжий 175р • Двойной свино-говяжий 235р • Свино-говяжий с сыром 235р • Свино-говяжий с грибами 210р • С бараниной 185р • Двойной с бараниной 255р • С бараниной и сыром 245р • С бараниной и грибами 220р БЛИНЧИКИ / НАЧИНКИ • С сёмгой и сливочным сыром 680р 200гр • Жюльен (курица с грибами) 485р 220гр • С куриным филе и овощами 370р 230гр • С сыром и зелёной 345р 170гр • С яблоком и корицей 270р 220гр • С творогом 475р 220гр • С нутеллой и бананом 390р 180гр • Блины со сгущёнкой (3 штуки) 235р 165гр ПАСТА • С курицей и грибами в сливочном соусе 485р 300гр • Паста с морепродуктами 710р 330гр • Паста с овощами 455р 300гр • Паста Карбонара 510р 300гр • Удон с овощами и курицей 485р 350гр ДЕСЕРТЫ • Яблочный штрудель с мороженым 410р 150гр • Пряник имбирный 250р • Тирамису 395р • Медовик 340р 120гр • Наполеон 440р 220гр • Эклер «Ванильный» 220р 1шт • Эклер «Шоколадный» 220р 1шт • Эклер «Карамельный» 220р 1шт • Прага 340р 140гр • Мороженое фруктовая «Феерия» (шоколадное/белое/фисташка) 420р 200гр • Мороженое «Коктейль» (шоколадное/белое/фисташка) 420р 200гр • Венские вафли с ягодами, мороженым, медом/сгущенным молоком 450р 180гр • Чизкейк 450р 175гр ПИЦЦА • Мясной пир 920р • Карбонара 650р • Маргарита 560р • Четыре сыра 760р • Цезарь 710р • Море 920р • Пепперони 650р ЧАЙ • Глинтвейн 420р 400мл • Какао 220р 300мл • Какао 285р 400мл • Какао на растительном молоке 265р 300мл • Какао на растительном молоке 325р 400мл • Горячий шоколад 275р 250мл • Горячий шоколад (густой) 325р 200мл • Молоко 100р 250мл • Чай заварной 320р 900мл • Чай имбирный 360р 900мл • Авторский чай 380р 900мл • Чай витаминный 395р 900мл • Натуральный чай 380р 650мл (черная смородина / облепиха / клюква) ДОБАВКИ К НАПИТКАМ • Молоко (добавка) 35р • Сироп (добавка) 45р • Мёд (добавка) 45р • Сливки (добавка) 45р ХОЛОДНЫЕ НАПИТКИ • Святой Источник 90р 500гр • Святой Источник 125р 1000гр • Боржоми 290р 500гр • Молочный коктейль ванильный / шоколадный 340р 400гр • Молочный коктейль банановый / клубничный 360р 400гр • Мохито 320р 400гр • Сок в ассортименте 110р 250гр • Сок в ассортименте 440р 1000гр • Фраппе 340р 400гр • Смузи банан и вишня 285р 400гр • Смузи банан и клубника 285р 400гр • Смузи банан и малина 315р 400гр • Смузи ягодный (малина, клубника, вишня) 360р 400гр • Фреш апельсиновый 360р 250гр • Фреш грейпфруктовый 360р 250гр • Натуральный лимонад 320р 500гр • Натуральный лимонад 640р 1000гр КОФЕ • Эспрессо 130р 30мл • Допио 260р 60мл • Макиато 150р 35мл • Флэт уайт 270р 120мл • Лунго 130р 50мл • Амернкано 130р 160мл • Амернкано 260р 300мл • Капучино 195р 250мл • Капучино 320р 400мл • Мокачино 220р 250мл • Мокачино 265р 400мл • Раф 290р 330мл • Раф 325р 400мл • Гляссе 240р 250мл • Айс латте 295р 400мл На растительном молоке: • Капучино 270р 250мл • Капучино 395р 400мл • Латте 310р 330мл • Латте 360р 400мл Латте: • Классический 240р 330мл • Классический 265р 400мл • Медовый 270р 330мл • Медовый 295р 400мл • Кедровый 300р 330мл • Кедровый 325р 400мл • Кокос 270р 330мл • Кокос 295р 400мл • Snickers 300р 330мл • Snickers 325р 400мл • Bounty 300р 330мл • Bounty 325р 400мл • С маршмеллоу 300р 330мл • С маршмеллоу 325р 400мл • С сиропом 270р 330мл • С сиропом 295р 400мл
A11: Рестораны | C11: Мыс Фиолент | D11: «Мыс Фиолент» - панорамный ресторан в самом живописном месте Крыма. ⠀ Морская лазурь, закаты, отвесные скалы и атмосфера, которую невозможно забыть. Интерьер сочетает стиль, комфорт и лёгкость: здесь будет уютно и на романтическом ужине, и за большим столом с друзьями. ⠀ Средиземноморская кухня с авторским акцентом, морепродукты, локальные специалитеты и винная карта, в которую влюбляются с первого бокала. ⠀ Ресторан расположен прямо на краю мыса Фиолент - для тех, кто ценит вкус, эстетику и вид, от которого захватывает дух. ⠀ Работает детская комната. | F11: Фиолентовское шоссе, 134 | G11: Фиолент | H11: 44.505011, 33.484844 | I11: https://avatars.mds.yandex.net/get-altay/5098065/2a00000181b454fb140f34d703eb4d6d02d3/XXXL | J11: https://vk.com/club169514262 | N11: +7 (978) 940-08-00 Свадьбы и торжества: +7 (978) 553-51-51 | O11: ⌚️Пн-Пт: с 12:00 до 23:00 Сб-Вс: с 12:00 до 00:00 | P11: {=_xlfn.XLOOKUP(C11, 'Меню Справочник'!A:A, 'Меню Справочник'!D:D, "Меню не заполнено")} -> Холодные закуски Парма с местными сырами 1100 ₽ Мезе хумус хрустящий баклажан 450 ₽ Мезе гуакамоле креветка 550 ₽ Мезе маринованные оливки греческий сыр 550 ₽ Брускетта со слабосоленой форелью и страчателлой 890 ₽ Брускетта с ростбифом и печеными перцами 750 ₽ Тартар из говядины с красной икрой и муссом пармезан 950 ₽ Тартар из говядины н мозговой коти 850 ₽ Тартар из форели с манго в авокадо 950 ₽ Десерты Тирамису 550 ₽ Муссовый десерт с бергамотом 550 ₽ Базиликовая панна-кота 450 ₽ Опера 550 ₽ Малиновый 550 ₽ Мороженое от Roberto Gelato 240 ₽ Сезонные фрукты и ягоды 1200 ₽ Гарниры Кукуруза гриль с паприкой и пармезаном 450 ₽ Грибы из угольной печи 380 ₽ Картофель по-деревенски 350 ₽ Картофель фри с пармезаном и трюфельным маслом 450 ₽ Хумус 350 ₽ Горячие закуски Запеченный баклажан со страчателлой и креветкой 790 ₽ Запеченный камамбер в угольной печи с сезонными ягодами 950 ₽ Мидии в створках в соусе дорблю 950 ₽ Мидии в створках в винном соусе 850 ₽ Мидии в створках с соусом из свежих томатов 850 ₽ Супы Гаспаччо с молодым горошком, страчателлой и клубникой 650 ₽ Окрошка на квасе 550 ₽ Окрошка на кефире 550 ₽ Буйабес с черноморской рыбой и вонголе 1200 ₽ Сырный крем-суп с фетой и хрустящим базиликом 690 ₽ Угольная печь Говяжьи медальоны 850 ₽ Стейк Стриплойн 1200 ₽ Стейк Денвер 650 ₽ Стейк Рибай 1770 ₽ Овощи гриль 450 ₽ Мясо Утиное филе в кофейном демигласе с яблочным пюре 870 ₽ Каре крымского ягненка (подается со свежим салатом и маринованным ялтинским луком) 1750 ₽ Свиной ошеек с молодым картофелем 820 ₽ Цыпленок корнишон на тортилье в соусе чимичурри 870 ₽ Пасты & Ризотто Спагетти с сыром страчателла в соусе из свежих томатов 690 ₽ Спагетти в соусе белое вино с вонголе 750 ₽ Лимонное ризотто с гребешком 850 ₽ Ризотто с белыми грибами и муссом пармезан 850 ₽ Салаты Буратта с разными томатами и клубникой 1200 ₽ Салат со слабосоленой форелью и сыром страчателла 950 ₽ Салат с апельсиновым маслом и тигровой креветкой 750 ₽ Салат из свежих овощей с сыром фета и артишоком 750 ₽ Детское меню Пельмешки светофор 450 ₽ Нежные куриные котлетки с макарошками 450 ₽ Овощные палочки (морковь, огурец, романо, перец сладкий) 250 ₽ Суп с куриными шариками 350 ₽ Кофе Эспрессо150 ₽ Допио200 ₽ Американо150 ₽ Рыба Горбыль в угольной печи с соусом чимичурри 1450 ₽ Судак в средиземноморском соусе 850 ₽ Стейк форели на гриле 1450 ₽
A12: Кафе | C12: Царское село | F12: ТСН СТ Фиолент, 457 | G12: Фиолент | H12: 44.507791, 33.486580 | I12: https://avatars.mds.yandex.net/get-altay/14336229/2a00000197b742608d97b8932637c0f65863/XXXL | N12: +7 (978) 280-94-45 | O12: ⌚️Пн-Вс 09:00 - 21:00 | P12: {=_xlfn.XLOOKUP(C12, 'Меню Справочник'!A:A, 'Меню Справочник'!D:D, "Меню не заполнено")} -> • Ланч 300р • Окрошка "Дальневосточная" 350р • Шашлык (под заказ) 300р 100гр • Запечённые овощи 200р 100гр • Бургер (свинная котлета) 400р • Хот дог 200р • Сырники 80р 1шт • Блинчики (с джемом, сгущёнкой) 80р 2шт • Орешки со сгущёнкой 30р 1шт • Кофе Американо 100р • Кофе Эспрессо 70р • Кофе с молоком 120р • Чай 50р
A13: Кофе | C13: Философия | D13: Кофейня «Философия» - это место, где можно насладиться вкусным кофе, свежей выпечкой и приятной атмосферой. | F13: Фиолентовское ш., 134, корп. 4 | G13: Фиолент | H13: 44.505425, 33.486418 | I13: https://avatars.mds.yandex.net/get-altay/13930885/2a00000191d9dd5e180e4451cc0750a75dca/XXXL | K13: https://t.me/Fiolent_Filosofia_Menu | N13: +7 (978) 334-24-28 | O13: ⌚️Пн-Вс 09:00 - 20:00 | P13: {=_xlfn.XLOOKUP(C13, 'Меню Справочник'!A:A, 'Меню Справочник'!D:D, "Меню не заполнено")} -> САЛАТЫ • Цезарь с курицей 290р • Цезарь с лососем 340р • Греческий салат 270р • Поке с булгуром и курицей 320р • Поке с рисом и лососем 380р СУПЫ • Куриный с лапшой 280р • Том Ям с курицей 340р • Том Ям с креветками 360р • Грибной крем-суп 290р • Тыквенный крем-суп 280р ЗАВТРАКИ• Омлет классический, запечённый 200р 200гр • Сырники 250р 3шт • Блинчики сладкие с яблоком и корицей 250р 4шт • Блинчики сладкие с творогом 250р 4шт • Блинчики сытные с ветчиной и сыром 320р 4шт • Блинчики сытные с мясом 320р 4шт
A14: Доставки | C14: Батя Жарит | D14: Мы - семейная доставка еды «Батя Жарит» в Севастополе! Наша команда уже больше 7 лет занимается производством и доставкой готовых блюд по всему городу! | F14: улица Меньшикова, 1А | G14: Муссон | H14: 44.598475, 33.481765 | I14: https://батя-жарит.рф/uploads/catalog/fon_dljaperehodasajt2.jpg | J14: https://vk.ru/bzh_sev | K14: https://t.me/bzh_sev | M14: https://xn----7sbbb1an9cmf8j.xn--p1ai/ | N14: +7 978 204 84 04 | O14: ⌚️Пн-Вс 10:00 - 22:00 | P14: {=_xlfn.XLOOKUP(C14, 'Меню Справочник'!A:A, 'Меню Справочник'!D:D, "Меню не заполнено")} -> МАНГАЛ Кебаб из свинины 200 г 450 ₽ Цыплёнок 250 г 790 ₽ Перепёлка 150 г 590 ₽ Стейк из свинины 200 г 560 ₽ Шашлык из филе бедра 200 г 520 ₽ Шашлык из свинины 200 г 520 ₽ Шашлык из курицы 200 г 480 ₽ Грибочки гриль 200 г 410 ₽ Кебаб из говядины 200 г 560 ₽ Куриные крылышки 200 г 360 ₽ Овощи гриль 300 г 440 ₽ Ребра гриль 200 г 460 ₽ Скумбрия на огне 300 г 750 ₽ Выпечка Пицца «4 сыра с кешью» 30 см 630 ₽ Пицца «6 сыров» 30 см 720 ₽ Пицца «Ветчина и грибы с кешью» 30 см 660 ₽ Пицца «Ветчина и картошка» 30 см 650 ₽ Пицца «Гавайская» 30 см 650 ₽ Пицца «Груша Дор блю» 30 см 620 ₽ Пицца «Капричоза» 30 см 690 ₽ Пицца «Лосось с грушей и дор блю» 30 см 890 ₽ Пицца «Маргарита с песто» 30 см 500 ₽ Пицца «Океаника» 30 см 820 ₽ Пицца «Охотничья» 30 см 690 ₽ Пицца «Пепперони с вялеными томатами на медовом соусе» 30 см 640 ₽ Пицца «Пепперони Спайси» 30 см 600 ₽ Пицца «Пепперони» 30 см 590 ₽ Пицца «Супер Батя» 30 см 670 ₽ Пицца «Том ям» 30 см 790 ₽ Пицца «Цезарь» 30 см 650 ₽ Пицца «Цыпленок Барбекю» 30 см 610 ₽ Пицца «Цыпленок Песто» 30 см 650 ₽ Пицца «Цыпленок Терияки» 30 см 610 ₽ Бамбино от 2 730 ₽ от 2 599 ₽ Дабл от 1 220 ₽ от 1 159 ₽ Вай-Вай от 890 ₽ от 849 ₽ Квартет от 1 910 ₽ от 1 819 ₽ Лодочка «Мидии и халапеньо» 300 г 540 ₽ Лодочка «Вишня на чиле» 300 г 480 ₽ Лодочка «Маршмелладзе» 300 г 540 ₽ Лодочка «Сырная» 350 г 420 ₽ Лодочка «Пепперони и Фета» 350 г 480 ₽ Лодочка «Курица и тигровая креветка» 350 г 560 ₽ Лодочка «Курица и грибы» 350 г 460 ₽ Лавашик "Ветчина и Сыр" 250 г 290 ₽ Лавашик "Томаты и Сыр" 260 г 270 ₽ Лавашик "Дабл Сыр" 320 г 370 ₽ Лавашик "Курочка и Сладкий чили" 330 г 370 ₽ Лавашик "Лосось Спайси" 220 г 390 ₽ Лепёшка 250 г 120 ₽ Лаваш 80 г 60 ₽ Роллы Нуар от 1 810 ₽ от 1 267 ₽ Галактика от 6 240 ₽ от 5 616 ₽ Калейдоскоп от 3 910 ₽ от 3 519 ₽ Калифорникейшн от 2 360 ₽ от 2 124 ₽ Лайт от 1 670 ₽ от 1 500 ₽ Мега Дракон от 4 020 ₽ от 3 618 ₽ Мега Мама от 4 470 ₽ от 4 023 ₽ Огненный от 3 270 ₽ от 2 943 ₽ Четвёрочка от 2 660 ₽ от 2 394 ₽ Калифорния Краб Роял 590 ₽ Калифорния Краб Спайси 390 ₽ Калифорния Краб Сырная 480 ₽ Калифорния Сяке Ред Роял 660 ₽ Калифорния Сяке Ред Спайси 570 ₽ Калифорния Сяке Ред Сырная 630 ₽ Калифорния Томаго Аво Роял 630 ₽ Калифорния Томаго Аво Спайси 510 ₽ Калифорния Томаго Аво Сырная 600 ₽ Урамаки Эби Роял 660 ₽ Урамаки Эби Спайси 560 ₽ Урамаки Эби Сырная 630 ₽ Футо Аво Роял 520 ₽ Футо Аво Спайси 330 ₽ Футо Аво Сырная 420 ₽ Футо Магуро Роял 660 ₽ Футо Магуро Спайси 490 ₽ Футо Магуро Сырная 590 ₽ Футо Мидийный Роял 590 ₽ Футо Мидийный Спайси 390 ₽ Футо Мидийный Сырная 490 ₽ Футо Сяке Огурец Роял 660 ₽ Футо Сяке Огурец Спайси 490 ₽ Футо Сяке Огурец Сырная 590 ₽ Футо Томаго Эби Роял 620 ₽ Футо Томаго Эби Спайси 420 ₽ Футо Томаго Эби Сырная 540 ₽ Футо Унаги Роял Фиш 670 ₽ Футо Унаги Спайси 500 ₽ Футо Унаги Сырная 600 ₽ Темпура Краб 400 ₽ Темпура Магуро 430 ₽ Темпура Сяке 480 ₽ Темпура Унаги 480 ₽ Темпура Эби 460 ₽ Ролл Цезарь с Креветкой 450 ₽ Ролл Цезарь с Курицей 370 ₽ Урамаки Аво Грин Чиз 450 ₽ Урамаки Аво Огурец 420 ₽ Урамаки Краб 370 ₽ Урамаки Магуро 520 ₽ Урамаки Сяке 550 ₽ Урамаки Унаги 560 ₽ Урамаки Цезарь Ред Чиз 460 ₽ Урамаки Эби 470 ₽ Урамаки Эби Ред Чиз 490 ₽ Калифорния Аво 350 ₽ Калифорния Краб 300 ₽ Калифорния Краб Блэк Чиз 430 ₽ Калифорния Магуро 480 ₽ Калифорния Сяке 480 ₽ Калифорния Сяке Ред Чиз 590 ₽ Калифорния Томаго Аво 420 ₽ Калифорния Томаго Грин Чиз 510 ₽ Калифорния Томаго Краб 330 ₽ Калифорния Томаго Магуро 480 ₽ Калифорния Томаго Сяке 550 ₽ Калифорния Томаго Унаги 540 ₽ Калифорния Томаго Эби 340 ₽ Калифорния Томаго Эби Блэк Чиз 470 ₽ Калифорния Унаги 640 ₽ Калифорния Эби 460 ₽ Маки Аво Блэк Чиз 350 ₽ Маки Авокадо 240 ₽ Маки Краб 200 ₽ Маки Магуро 340 ₽ Маки Огурец 190 ₽ Маки Сяке 380 ₽ Маки Томаго 190 ₽ Маки Эби Спайси 350 ₽ Унаги Маки 410 ₽ Футо Аво Огурец 250 ₽ Футо Краб Ананас 290 ₽ Футо Краб-Мидии 430 ₽ Футо Магуро Чиз 390 ₽ Футо Мидии Ред Чиз 430 ₽ Футо Сяке Грин Чиз 540 ₽ Футо Сяке Огурец 390 ₽ Футо Сяке Чиз 440 ₽ Футо Томаго Эби 360 ₽ Футо Унаги Аво 450 ₽ Футо Унаги Блэк Чиз 560 ₽ Футо Фулл Грин 350 ₽ Фила Дабл Сяке 790 ₽ Фила Дабл Чиз 590 ₽ Фила Магуро 660 ₽ Фила Сяке 690 ₽ Фила Сяке Аво 720 ₽ Фила Сяке Огурец 680 ₽ Фила Сяке с Магуро и Аво 850 ₽ Фила Сяке Томаго 680 ₽ Фила Сяке Эби с Аво 820 ₽ Фила Унаги 670 ₽ Фила Эби 640 ₽ Дракон Белый 590 ₽ Дракон Жёлтый 540 ₽ Дракон Зелёный 690 ₽ Дракон Красный 790 ₽ Дракон Розовый 620 ₽ Дракон Чёрный 790 ₽ Мидии запеченные спайси 160 г 5 шт 390 ₽ Мидии запеченные с шапкой 160 г 5 шт 490 ₽ Стритфуд Грибной донер в лаваше 250 г 380 ₽ Донер с фалафелем в лаваше 250 г 340 ₽ Куриный донер в лаваше 300 г 400 ₽ Люля в лаваше 270 г 380 ₽ НеГирос в лаваше 300 г 380 ₽ Свиной донер в лаваше 300 г 450 ₽ Сырный донер в лаваше 230 г 380 ₽ Грибной донер в хлебе 270 г 390 ₽ Куриный донер в хлебе 320 г 410 ₽ НеГирос в хлебе 320 г 390 ₽ Овощной донер в хлебе 250 г 360 ₽ Свиной донер в хлебе 320 г 460 ₽ Бургер «Батяня» 320 г 560 ₽ Бургер «Брусничный» 330 г 620 ₽ Бургер «Бэби» 290 г 490 ₽ Бургер «Грибник» 320 г 560 ₽ Бургер «Цезарио с яйцом» 330 г 540 ₽ Бургер «Цезарио» 300 г 490 ₽ Бургер «Чиз-чиз» 330 г 590 ₽ Картофель фирменный 200 г 250 ₽ Картофель фри 100 г 170 ₽ Кольца кальмара 6 шт 120 г 390 ₽ Кольца кальмара 9 шт 180 г 580 ₽ Креветки панко 9 шт 180 г 720 ₽ Креветки панко 6 шт 110 г 480 ₽ Луковые кольца 9 шт 110 г 270 ₽ Луковые кольца 6 шт 70 г 180 ₽ Наггетсы 9 шт 162 г 360 ₽ Наггетсы 6 шт 108 г 240 ₽ Сырные палочки 9 шт 180 г 390 ₽ Сырные палочки 6 шт 120 г 290 ₽ Один плюс Один 600 г от 850 ₽ от 809 ₽ Фрибокс «Чикен» 200 г 370 ₽ Фрибокс «Хот» 200 г 380 ₽ Фрибокс «Читмил» 200 г 380 ₽ Фрибокс «Машрум» 200 г 360 ₽ Комбо Большой Батя 800 г от 1 660 ₽ от 1 580 ₽ МегаБатя 1600 г от 3 620 ₽ от 3 440 ₽ МиниБатя 600 г от 1 250 ₽ от 1 190 ₽ Ультра Батя 3200 г от 7 240 ₽ от 6 880 ₽ Чикен Сет 300 г от 490 ₽ от 465 ₽ Эконом Сет 300 г от 510 ₽ от 485 ₽ Эпический Батя 5600 г от 12 500 ₽ от 11 880 ₽ Бамбино от 2 730 ₽ от 2 599 ₽ Дабл от 1 220 ₽ от 1 159 ₽ Вай-Вай от 890 ₽ от 849 ₽ Квартет от 1 910 ₽ от 1 819 ₽ Пятница 448 г от 1 090 ₽ от 1 029 ₽ Один плюс Один 600 г от 850 ₽ от 809 ₽ Салаты и закуски Салат "Цезарь" с лососем 250 г 620 ₽ Салат с баклажаном 250 г 370 ₽ Овощной салат 250 г 340 ₽ Салат овощной с брынзой 250 г 380 ₽ Салат "Цезарь" с копченой курицей 250 г 440 ₽ Столичный салат 250 г 360 ₽ Салат из овощей гриль 250 г 440 ₽ Капрезе от Бати 250 г 290 ₽ Домашние соленья 250 г 350 ₽ Маринованный лук 50 г 35 ₽ Супы Финская уха 400 г 490 ₽ Том-ям с морепродуктами 400 г 590 ₽ Том-ям с курицей 400 г 450 ₽ Лагман с говядиной 300 г 490 ₽ Солянка мясная 300 г 460 ₽ Суп с фрикадельками 300 г 380 ₽ Суп куриный с домашней лапшой 300 г 250 ₽ Десерты Чизкейк манго-маракуйя 100 г Лодочка «Вишня на чиле» 300 г 480 ₽ Лодочка «Маршмелладзе» 300 г 540 ₽ Чизкейк шоколадный 100 г 200 ₽ Чизкейк классический 100 г 190 ₽ Напитки Фирменный компот 330 мл 120 ₽ Сок J7 в ассортименте 1000 мл от 340 ₽ Лимонад "Натахтари" 500 мл от 220 ₽ Evervess кола 500 мл 140 ₽ Frustyle апельсин 500 мл 140 ₽ Frustyle лимон-лайм 500 мл 140 ₽ Lipton зеленый чай 500 мл 160 ₽ Lipton лимон 500 мл 160 ₽ Aque Minerale негазированная 500 мл 100 ₽ Aque Minerale газированная 500 мл 100 ₽ Соусы Барбекю ® 30 г 70 ₽ Тартар ® 30 г 50 ₽ Бургер ® 30 г 50 ₽ Аджика ® 30 г 50 ₽ Батя ® 30 г 50 ₽ Батя Спайси ® 30 г 50 ₽ Чесночный ® 30 г 50 ₽ Кетчуп 30 г 30 ₽ Цезарь ® 30 г 50 ₽ Брусничный 30 г 50 ₽ Кисло-сладкий 30 г 50 ₽ Сырный 30 г 50 ₽ Грибной 30 г 50 ₽
A15: Доставки | C15: Гастрокондитерская Т.Д. | D15: Гастрономия в ритме Вашего дня Освободи время для важных дел. Готовая еда в удобном формате. | F15: ул. Льва Толстого, 64 | G15: ГорГаз | H15: 44.584912, 33.508067 | I15: https://encrypted-tbn0.gstatic.com/images?q=tbn:ANd9GcRuJ3IAtuALXiE1HFLrn0SycfhJBBRDHUKldQ&s | J15: https://vk.com/t.d.gastrokonditerskaya | K15: https://t.me/td_gastrokonditerskaya | M15: https://gastrotd.ru/ | N15: +7 (978) 458‑12‑28 | O15: ⌚️Пн-Вс 08:00 - 21:00 | P15: {=_xlfn.XLOOKUP(C15, 'Меню Справочник'!A:A, 'Меню Справочник'!D:D, "Меню не заполнено")} -> Завтраки Блины с куриным жульеном 180 г 239р Блины с творогом и изюмом 180 г 225р Сырники 190 г 239р Блины с ветчиной и сыром 180 г 239р Суфле творожное со смородиной 180 г 225р Омлет с грибами и колбасками 225 г 286р Сендвич с ветчиной 170 г 225р Сендвич с Индейкой 190 г 255р Комбо-завтраки Завтрак Дуэт #1 459р Завтрак Дуэт #2 529р Завтрак Дуэт #3 449р Завтрак Дуэт #4 449р Завтрак "3 правильных дня" #1 1419р Завтрак "3 правильных дня" #2 1396р Завтрак "3 правильных дня" #3 1469р Супы Борщ с говядиной и фасолью 370 г 319р Куриный бульон 370 г 289р Окрошка на кефире 390 г 320р Суп Том-Ям 370 г 389р Солянка мясная 350 г 329р Комбо-обеды Обед Дуэт популярных #1 629р Обед Дуэт популярных #2 629р Обед Дуэт популярных #3 629р Обед Дуэт популярных #4 569р Обед Дуэт #1 636р Обед Дуэт #3 619р Обед Дуэт #4 599р "3 Дня с обедом" #1 1699р "3 Дня с обедом" #2 1786р "3 Дня с обедом" #3 1799р Салаты Салат Цезарь с креветкой 152 г 359р Салат с печеными овощами 200 г 329р Боул с курицей и киноа 235 г 289р Салат Зеленый с индейкой 185 г 295р Салат "Не Крабовый" 220 г 295р Салат "Оливия" 210 г 360р Салат Индейка с дорблю и апельсином 180 г 325р Оливье с подкопчённой индейкой 260 г 296р Салат Не Греческий 200 г 290р Салат Цезарь с цыпленком 180 г 296р Основные блюда Запечённое куриное филе с гречкой и грибами 319 ₽ Бефстроганов с картофельным пюре 275 г 339р Куриные котлетки с картофельным пюре 220 г 319р Паста Карбонара 246 г 320р Котлета куриная паровая с рисом 270 г 275р Котлета рыбная с пюре 240 г 296р Фузилли с курицей и грибами 243 г 325р Филе минтая с овощами 245 г 359р Удон с курицей 250 г 255р Тефтели в пряном соусе 280 г 289р Биточки из индейки с черным рисом 285 г 290р Паста с фрикадельками из индейки 280 г 360р Куриное филе Спайси 270 г 375р Котлета рубленая с булгуром 250 г 296р Комбо-ужины на 3 дня "Ужин Сама готовила" #1 1749р "Ужин Сама готовила" #2 1759р "Ужин Сама готовила" #3 1759р Большие порции Борщ "Не для одного" 500 г 449р Солянка мясная "Не для одного" 500 г 439р Супер Карбонара "Не для одного" 500 г 596р Тефтели в пряном соусе "Не для одного" 600 г 869р Булгур со сливочным маслом "Не для одного" 500 г 289р Пюре картофельное "Не для одного" 500 г 349р Рис пряный "Не для одного" 500 г 289р Всё включено Рацион "Все включено" #1 5279р Рацион "Все включено" #2 4596р Рацион "Все включено" #3 5136р Дополнительно Сметана 30 г 60р Хлеб Чиабатта 70 г 65р Заморозка Блины с ветчиной и сыром зам. 525 г 495р Блины с куриным жульеном зам. 525 г 495р Блины с творогом и изюмом зам. 525 г 415р Котлеты куриные зам. 500 г 515р Котлеты рыбные зам. 450 г 460р Сырники зам. 500 г 390р Тефтели из говядины и свинины зам. 600 г 530р Котлеты паровые куриные зам. 470 г 495р Фуршет Заказ за 3 дня Гастробокс "Кростини Летний баланс" 4500р Гастробокс "BBQ" 6800р Гастробокс "WOW" 5100р Гастробокс "Тарты Оливье" 2800р Гастробокс "Салаты Веррины" 5800р Гастробокс "Закусочный" 5300р Гастробокс "Сырный краш" 4990р Гастробокс "Tartaletto" 6200р Гастробокс "Сливки сезона" 2700р Гастробокс "Страны мира" 5600р Гастробокс "Пикник" 6300р Гастробокс "Клаб сендвич" 5600р Гастробокс "Не сладкие чизкейки" 5500р Гастробокс "Лимонкота" 3400р Гастробокс "Романтический ужин" 4000р Гастробокс "Тарталетки 3 вкуса" 4990р Гастробокс "Жюльен классический" 3200р Гастробокс "Жюльен морской" 3500р Гастробокс "Рулетики из карбонада" 3499р Гастробокс "Кростини 6 вкусов" 4900р Гастробокс "Брускетты 4 вкуса" 4500р Гастробокос "Клаб канапе" 3600р Гастробокс "Цезарь" 5000р Гастробокс "Под крепкие" 5300р Гастробокс "Под вино" 6100р Гастробокс "Канапе ХЛ" 4900р Гастробокс "Под шампусик" 6300р Гастробокс "Пир закусок" 5500р Гастробокс "Креветки в панко" 20*20 3150р Гастробокс "Креветки в панко" 25*25 4450р Торты Заказ за 2 дня Баунти 750 г 1050р Красный бархат 900 г 1280р Латте - Макиато 850 г 1200р Шоколад Малина 960 г 1350р Медовик 600 г 900р Меренговый рулет 400 г 720р Молочная девочка 1000 г 1350р Грушевый 750 г 1050р Киевский 650 г 1430р Наполеон 600 г 750р Нежняя осень 900 г 1220р Пражский 850 г 1250р Торт Йогуртовый персик 850 г 1150р Три шоколада 700 г 1050р Чизкейк классический 900 г 1500р Шоколад - Фундук 1000 г 1890р Вишня - Шоколад 1100 г 1850р Летняя нежность 450 г 890р Десерты Вафельная трубочка со сгущенкой 159р Картошка 55 г 80р
A16: Кондитерские | C16: Т.Д. | D16: Кондитерская «Т. Д.» - это место, где вы можете насладиться свежими и вкусными десертами, такими как торты, пирожные и круассаны, а также выпить кофе и другие напитки. В кондитерской часто проводятся акции, например, «2+1», когда вы берете два кусочка десерта, а третий дается бесплатно. | F16: просп. Генерала Острякова, 198В | G16: Остряки (38ая школа) | H16: 44.559115, 33.527425 | I16: https://avatars.mds.yandex.net/get-altay/10095165/2a00000190c0a2fecc603ec8835b53279f9b/XXXL | J16: https://vk.com/t.d.gastrokonditerskaya | K16: https://t.me/td_gastrokonditerskaya | M16: https://gastrotd.ru/ | N16: +7 (978) 178-99-56 По этому номеру можно заказать красивый вкусный торт и задать все интересующие вопросы💚 | O16: ⌚️Пн-Вс 08:00 - 21:00 | P16: {=_xlfn.XLOOKUP(C16, 'Меню Справочник'!A:A, 'Меню Справочник'!D:D, "Меню не заполнено")} -> Завтраки Блины с куриным жульеном 180 г 239р Блины с творогом и изюмом 180 г 225р Сырники 190 г 239р Блины с ветчиной и сыром 180 г 239р Суфле творожное со смородиной 180 г 225р Омлет с грибами и колбасками 225 г 286р Сендвич с ветчиной 170 г 225р Сендвич с Индейкой 190 г 255р Комбо-завтраки Завтрак Дуэт #1 459р Завтрак Дуэт #2 529р Завтрак Дуэт #3 449р Завтрак Дуэт #4 449р Завтрак ""3 правильных дня"" #1 1419р Завтрак ""3 правильных дня"" #2 1396р Завтрак ""3 правильных дня"" #3 1469р Супы Борщ с говядиной и фасолью 370 г 319р Куриный бульон 370 г 289р Окрошка на кефире 390 г 320р Суп Том-Ям 370 г 389р Солянка мясная 350 г 329р Комбо-обеды Обед Дуэт популярных #1 629р Обед Дуэт популярных #2 629р Обед Дуэт популярных #3 629р Обед Дуэт популярных #4 569р Обед Дуэт #1 636р Обед Дуэт #3 619р Обед Дуэт #4 599р ""3 Дня с обедом"" #1 1699р ""3 Дня с обедом"" #2 1786р ""3 Дня с обедом"" #3 1799р Салаты Салат Цезарь с креветкой 152 г 359р Салат с печеными овощами 200 г 329р Боул с курицей и киноа 235 г 289р Салат Зеленый с индейкой 185 г 295р Салат ""Не Крабовый"" 220 г 295р Салат ""Оливия"" 210 г 360р Салат Индейка с дорблю и апельсином 180 г 325р Оливье с подкопчённой индейкой 260 г 296р Салат Не Греческий 200 г 290р Салат Цезарь с цыпленком 180 г 296р Основные блюда Запечённое куриное филе с гречкой и грибами 319 ₽ Бефстроганов с картофельным пюре 275 г 339р Куриные котлетки с картофельным пюре 220 г 319р Паста Карбонара 246 г 320р Котлета куриная паровая с рисом 270 г 275р Котлета рыбная с пюре 240 г 296р Фузилли с курицей и грибами 243 г 325р Филе минтая с овощами 245 г 359р Удон с курицей 250 г 255р Тефтели в пряном соусе 280 г 289р Биточки из индейки с черным рисом 285 г 290р Паста с фрикадельками из индейки 280 г 360р Куриное филе Спайси 270 г 375р Котлета рубленая с булгуром 250 г 296р Комбо-ужины на 3 дня ""Ужин Сама готовила"" #1 1749р ""Ужин Сама готовила"" #2 1759р ""Ужин Сама готовила"" #3 1759р Большие порции Борщ ""Не для одного"" 500 г 449р Солянка мясная ""Не для одного"" 500 г 439р Супер Карбонара ""Не для одного"" 500 г 596р Тефтели в пряном соусе ""Не для одного"" 600 г 869р Булгур со сливочным маслом ""Не для одного"" 500 г 289р Пюре картофельное ""Не для одного"" 500 г 349р Рис пряный ""Не для одного"" 500 г 289р Всё включено Рацион ""Все включено"" #1 5279р Рацион ""Все включено"" #2 4596р Рацион ""Все включено"" #3 5136р Дополнительно Сметана 30 г 60р Хлеб Чиабатта 70 г 65р Заморозка Блины с ветчиной и сыром зам. 525 г 495р Блины с куриным жульеном зам. 525 г 495р Блины с творогом и изюмом зам. 525 г 415р Котлеты куриные зам. 500 г 515р Котлеты рыбные зам. 450 г 460р Сырники зам. 500 г 390р Тефтели из говядины и свинины зам. 600 г 530р Котлеты паровые куриные зам. 470 г 495р Фуршет Заказ за 3 дня Гастробокс ""Кростини Летний баланс"" 4500р Гастробокс ""BBQ"" 6800р Гастробокс ""WOW"" 5100р Гастробокс ""Тарты Оливье"" 2800р Гастробокс ""Салаты Веррины"" 5800р Гастробокс ""Закусочный"" 5300р Гастробокс ""Сырный краш"" 4990р Гастробокс ""Tartaletto"" 6200р Гастробокс ""Сливки сезона"" 2700р Гастробокс ""Страны мира"" 5600р Гастробокс ""Пикник"" 6300р Гастробокс ""Клаб сендвич"" 5600р Гастробокс ""Не сладкие чизкейки"" 5500р Гастробокс ""Лимонкота"" 3400р Гастробокс ""Романтический ужин"" 4000р Гастробокс ""Тарталетки 3 вкуса"" 4990р Гастробокс ""Жюльен классический"" 3200р Гастробокс ""Жюльен морской"" 3500р Гастробокс ""Рулетики из карбонада"" 3499р Гастробокс ""Кростини 6 вкусов"" 4900р Гастробокс ""Брускетты 4 вкуса"" 4500р Гастробокос ""Клаб канапе"" 3600р Гастробокс ""Цезарь"" 5000р Гастробокс ""Под крепкие"" 5300р Гастробокс ""Под вино"" 6100р Гастробокс ""Канапе ХЛ"" 4900р Гастробокс ""Под шампусик"" 6300р Гастробокс ""Пир закусок"" 5500р Гастробокс ""Креветки в панко"" 20*20 3150р Гастробокс ""Креветки в панко"" 25*25 4450р Торты Заказ за 2 дня Баунти 750 г 1050р Красный бархат 900 г 1280р Латте - Макиато 850 г 1200р Шоколад Малина 960 г 1350р Медовик 600 г 900р Меренговый рулет 400 г 720р Молочная девочка 1000 г 1350р Грушевый 750 г 1050р Киевский 650 г 1430р Наполеон 600 г 750р Нежняя осень 900 г 1220р Пражский 850 г 1250р Торт Йогуртовый персик 850 г 1150р Три шоколада 700 г 1050р Чизкейк классический 900 г 1500р Шоколад - Фундук 1000 г 1890р Вишня - Шоколад 1100 г 1850р Летняя нежность 450 г 890р Десерты Вафельная трубочка со сгущенкой 159р Картошка 55 г 80р "
A17: Кондитерские | C17: Т.Д. | D17: Кондитерская «Т. Д.» - это место, где вы можете насладиться свежими и вкусными десертами, такими как торты, пирожные и круассаны, а также выпить кофе и другие напитки. В кондитерской часто проводятся акции, например, «2+1», когда вы берете два кусочка десерта, а третий дается бесплатно. | F17: ул. Пожарова 20/3 | G17: Цирк | H17: 44.603868, 33.505325 | I17: https://avatars.mds.yandex.net/get-altay/15417312/2a00000197c5c32bb79c55963f0fd4e6fb69/XXXL | J17: https://vk.com/t.d.gastrokonditerskaya | K17: https://t.me/td_gastrokonditerskaya | M17: https://gastrotd.ru/ | N17: +7 (978) 178-99-56 По этому номеру можно заказать красивый вкусный торт и задать все интересующие вопросы💚 | O17: ⌚️Пн-Вс 08:00 - 21:00 | P17: {=_xlfn.XLOOKUP(C16, 'Меню Справочник'!A:A, 'Меню Справочник'!D:D, "Меню не заполнено")} -> Завтраки Блины с куриным жульеном 180 г 239р Блины с творогом и изюмом 180 г 225р Сырники 190 г 239р Блины с ветчиной и сыром 180 г 239р Суфле творожное со смородиной 180 г 225р Омлет с грибами и колбасками 225 г 286р Сендвич с ветчиной 170 г 225р Сендвич с Индейкой 190 г 255р Комбо-завтраки Завтрак Дуэт #1 459р Завтрак Дуэт #2 529р Завтрак Дуэт #3 449р Завтрак Дуэт #4 449р Завтрак ""3 правильных дня"" #1 1419р Завтрак ""3 правильных дня"" #2 1396р Завтрак ""3 правильных дня"" #3 1469р Супы Борщ с говядиной и фасолью 370 г 319р Куриный бульон 370 г 289р Окрошка на кефире 390 г 320р Суп Том-Ям 370 г 389р Солянка мясная 350 г 329р Комбо-обеды Обед Дуэт популярных #1 629р Обед Дуэт популярных #2 629р Обед Дуэт популярных #3 629р Обед Дуэт популярных #4 569р Обед Дуэт #1 636р Обед Дуэт #3 619р Обед Дуэт #4 599р ""3 Дня с обедом"" #1 1699р ""3 Дня с обедом"" #2 1786р ""3 Дня с обедом"" #3 1799р Салаты Салат Цезарь с креветкой 152 г 359р Салат с печеными овощами 200 г 329р Боул с курицей и киноа 235 г 289р Салат Зеленый с индейкой 185 г 295р Салат ""Не Крабовый"" 220 г 295р Салат ""Оливия"" 210 г 360р Салат Индейка с дорблю и апельсином 180 г 325р Оливье с подкопчённой индейкой 260 г 296р Салат Не Греческий 200 г 290р Салат Цезарь с цыпленком 180 г 296р Основные блюда Запечённое куриное филе с гречкой и грибами 319 ₽ Бефстроганов с картофельным пюре 275 г 339р Куриные котлетки с картофельным пюре 220 г 319р Паста Карбонара 246 г 320р Котлета куриная паровая с рисом 270 г 275р Котлета рыбная с пюре 240 г 296р Фузилли с курицей и грибами 243 г 325р Филе минтая с овощами 245 г 359р Удон с курицей 250 г 255р Тефтели в пряном соусе 280 г 289р Биточки из индейки с черным рисом 285 г 290р Паста с фрикадельками из индейки 280 г 360р Куриное филе Спайси 270 г 375р Котлета рубленая с булгуром 250 г 296р Комбо-ужины на 3 дня ""Ужин Сама готовила"" #1 1749р ""Ужин Сама готовила"" #2 1759р ""Ужин Сама готовила"" #3 1759р Большие порции Борщ ""Не для одного"" 500 г 449р Солянка мясная ""Не для одного"" 500 г 439р Супер Карбонара ""Не для одного"" 500 г 596р Тефтели в пряном соусе ""Не для одного"" 600 г 869р Булгур со сливочным маслом ""Не для одного"" 500 г 289р Пюре картофельное ""Не для одного"" 500 г 349р Рис пряный ""Не для одного"" 500 г 289р Всё включено Рацион ""Все включено"" #1 5279р Рацион ""Все включено"" #2 4596р Рацион ""Все включено"" #3 5136р Дополнительно Сметана 30 г 60р Хлеб Чиабатта 70 г 65р Заморозка Блины с ветчиной и сыром зам. 525 г 495р Блины с куриным жульеном зам. 525 г 495р Блины с творогом и изюмом зам. 525 г 415р Котлеты куриные зам. 500 г 515р Котлеты рыбные зам. 450 г 460р Сырники зам. 500 г 390р Тефтели из говядины и свинины зам. 600 г 530р Котлеты паровые куриные зам. 470 г 495р Фуршет Заказ за 3 дня Гастробокс ""Кростини Летний баланс"" 4500р Гастробокс ""BBQ"" 6800р Гастробокс ""WOW"" 5100р Гастробокс ""Тарты Оливье"" 2800р Гастробокс ""Салаты Веррины"" 5800р Гастробокс ""Закусочный"" 5300р Гастробокс ""Сырный краш"" 4990р Гастробокс ""Tartaletto"" 6200р Гастробокс ""Сливки сезона"" 2700р Гастробокс ""Страны мира"" 5600р Гастробокс ""Пикник"" 6300р Гастробокс ""Клаб сендвич"" 5600р Гастробокс ""Не сладкие чизкейки"" 5500р Гастробокс ""Лимонкота"" 3400р Гастробокс ""Романтический ужин"" 4000р Гастробокс ""Тарталетки 3 вкуса"" 4990р Гастробокс ""Жюльен классический"" 3200р Гастробокс ""Жюльен морской"" 3500р Гастробокс ""Рулетики из карбонада"" 3499р Гастробокс ""Кростини 6 вкусов"" 4900р Гастробокс ""Брускетты 4 вкуса"" 4500р Гастробокос ""Клаб канапе"" 3600р Гастробокс ""Цезарь"" 5000р Гастробокс ""Под крепкие"" 5300р Гастробокс ""Под вино"" 6100р Гастробокс ""Канапе ХЛ"" 4900р Гастробокс ""Под шампусик"" 6300р Гастробокс ""Пир закусок"" 5500р Гастробокс ""Креветки в панко"" 20*20 3150р Гастробокс ""Креветки в панко"" 25*25 4450р Торты Заказ за 2 дня Баунти 750 г 1050р Красный бархат 900 г 1280р Латте - Макиато 850 г 1200р Шоколад Малина 960 г 1350р Медовик 600 г 900р Меренговый рулет 400 г 720р Молочная девочка 1000 г 1350р Грушевый 750 г 1050р Киевский 650 г 1430р Наполеон 600 г 750р Нежняя осень 900 г 1220р Пражский 850 г 1250р Торт Йогуртовый персик 850 г 1150р Три шоколада 700 г 1050р Чизкейк классический 900 г 1500р Шоколад - Фундук 1000 г 1890р Вишня - Шоколад 1100 г 1850р Летняя нежность 450 г 890р Десерты Вафельная трубочка со сгущенкой 159р Картошка 55 г 80р "
A18: Кондитерские | C18: Т.Д. | D18: Кондитерская «Т. Д.» - это место, где вы можете насладиться свежими и вкусными десертами, такими как торты, пирожные и круассаны, а также выпить кофе и другие напитки. В кондитерской часто проводятся акции, например, «2+1», когда вы берете два кусочка десерта, а третий дается бесплатно. | F18: ул. Руднева 30А | G18: Муссон | H18: 44.592080, 33.494704 | I18: https://avatars.mds.yandex.net/get-altay/15270672/2a00000197882b9d90432f0f24c8d9bf9093/XXXL | J18: https://vk.com/t.d.gastrokonditerskaya | K18: https://t.me/td_gastrokonditerskaya | M18: https://gastrotd.ru/ | N18: +7 (978) 178-99-56 По этому номеру можно заказать красивый вкусный торт и задать все интересующие вопросы💚 | O18: ⌚️Пн-Вс 08:00 - 21:00 | P18: {=_xlfn.XLOOKUP(C16, 'Меню Справочник'!A:A, 'Меню Справочник'!D:D, "Меню не заполнено")} -> Завтраки Блины с куриным жульеном 180 г 239р Блины с творогом и изюмом 180 г 225р Сырники 190 г 239р Блины с ветчиной и сыром 180 г 239р Суфле творожное со смородиной 180 г 225р Омлет с грибами и колбасками 225 г 286р Сендвич с ветчиной 170 г 225р Сендвич с Индейкой 190 г 255р Комбо-завтраки Завтрак Дуэт #1 459р Завтрак Дуэт #2 529р Завтрак Дуэт #3 449р Завтрак Дуэт #4 449р Завтрак ""3 правильных дня"" #1 1419р Завтрак ""3 правильных дня"" #2 1396р Завтрак ""3 правильных дня"" #3 1469р Супы Борщ с говядиной и фасолью 370 г 319р Куриный бульон 370 г 289р Окрошка на кефире 390 г 320р Суп Том-Ям 370 г 389р Солянка мясная 350 г 329р Комбо-обеды Обед Дуэт популярных #1 629р Обед Дуэт популярных #2 629р Обед Дуэт популярных #3 629р Обед Дуэт популярных #4 569р Обед Дуэт #1 636р Обед Дуэт #3 619р Обед Дуэт #4 599р ""3 Дня с обедом"" #1 1699р ""3 Дня с обедом"" #2 1786р ""3 Дня с обедом"" #3 1799р Салаты Салат Цезарь с креветкой 152 г 359р Салат с печеными овощами 200 г 329р Боул с курицей и киноа 235 г 289р Салат Зеленый с индейкой 185 г 295р Салат ""Не Крабовый"" 220 г 295р Салат ""Оливия"" 210 г 360р Салат Индейка с дорблю и апельсином 180 г 325р Оливье с подкопчённой индейкой 260 г 296р Салат Не Греческий 200 г 290р Салат Цезарь с цыпленком 180 г 296р Основные блюда Запечённое куриное филе с гречкой и грибами 319 ₽ Бефстроганов с картофельным пюре 275 г 339р Куриные котлетки с картофельным пюре 220 г 319р Паста Карбонара 246 г 320р Котлета куриная паровая с рисом 270 г 275р Котлета рыбная с пюре 240 г 296р Фузилли с курицей и грибами 243 г 325р Филе минтая с овощами 245 г 359р Удон с курицей 250 г 255р Тефтели в пряном соусе 280 г 289р Биточки из индейки с черным рисом 285 г 290р Паста с фрикадельками из индейки 280 г 360р Куриное филе Спайси 270 г 375р Котлета рубленая с булгуром 250 г 296р Комбо-ужины на 3 дня ""Ужин Сама готовила"" #1 1749р ""Ужин Сама готовила"" #2 1759р ""Ужин Сама готовила"" #3 1759р Большие порции Борщ ""Не для одного"" 500 г 449р Солянка мясная ""Не для одного"" 500 г 439р Супер Карбонара ""Не для одного"" 500 г 596р Тефтели в пряном соусе ""Не для одного"" 600 г 869р Булгур со сливочным маслом ""Не для одного"" 500 г 289р Пюре картофельное ""Не для одного"" 500 г 349р Рис пряный ""Не для одного"" 500 г 289р Всё включено Рацион ""Все включено"" #1 5279р Рацион ""Все включено"" #2 4596р Рацион ""Все включено"" #3 5136р Дополнительно Сметана 30 г 60р Хлеб Чиабатта 70 г 65р Заморозка Блины с ветчиной и сыром зам. 525 г 495р Блины с куриным жульеном зам. 525 г 495р Блины с творогом и изюмом зам. 525 г 415р Котлеты куриные зам. 500 г 515р Котлеты рыбные зам. 450 г 460р Сырники зам. 500 г 390р Тефтели из говядины и свинины зам. 600 г 530р Котлеты паровые куриные зам. 470 г 495р Фуршет Заказ за 3 дня Гастробокс ""Кростини Летний баланс"" 4500р Гастробокс ""BBQ"" 6800р Гастробокс ""WOW"" 5100р Гастробокс ""Тарты Оливье"" 2800р Гастробокс ""Салаты Веррины"" 5800р Гастробокс ""Закусочный"" 5300р Гастробокс ""Сырный краш"" 4990р Гастробокс ""Tartaletto"" 6200р Гастробокс ""Сливки сезона"" 2700р Гастробокс ""Страны мира"" 5600р Гастробокс ""Пикник"" 6300р Гастробокс ""Клаб сендвич"" 5600р Гастробокс ""Не сладкие чизкейки"" 5500р Гастробокс ""Лимонкота"" 3400р Гастробокс ""Романтический ужин"" 4000р Гастробокс ""Тарталетки 3 вкуса"" 4990р Гастробокс ""Жюльен классический"" 3200р Гастробокс ""Жюльен морской"" 3500р Гастробокс ""Рулетики из карбонада"" 3499р Гастробокс ""Кростини 6 вкусов"" 4900р Гастробокс ""Брускетты 4 вкуса"" 4500р Гастробокос ""Клаб канапе"" 3600р Гастробокс ""Цезарь"" 5000р Гастробокс ""Под крепкие"" 5300р Гастробокс ""Под вино"" 6100р Гастробокс ""Канапе ХЛ"" 4900р Гастробокс ""Под шампусик"" 6300р Гастробокс ""Пир закусок"" 5500р Гастробокс ""Креветки в панко"" 20*20 3150р Гастробокс ""Креветки в панко"" 25*25 4450р Торты Заказ за 2 дня Баунти 750 г 1050р Красный бархат 900 г 1280р Латте - Макиато 850 г 1200р Шоколад Малина 960 г 1350р Медовик 600 г 900р Меренговый рулет 400 г 720р Молочная девочка 1000 г 1350р Грушевый 750 г 1050р Киевский 650 г 1430р Наполеон 600 г 750р Нежняя осень 900 г 1220р Пражский 850 г 1250р Торт Йогуртовый персик 850 г 1150р Три шоколада 700 г 1050р Чизкейк классический 900 г 1500р Шоколад - Фундук 1000 г 1890р Вишня - Шоколад 1100 г 1850р Летняя нежность 450 г 890р Десерты Вафельная трубочка со сгущенкой 159р Картошка 55 г 80р "
